2021-09-17 17:05:16.686739: W tensorflow/stream_executor/platform/default/dso_loader.cc:60] Could not load dynamic library 'libcudart.so.11.0'; dlerror: libcudart.so.11.0: cannot open shared object file: No such file or directory; LD_LIBRARY_PATH: /home/stefanovergani/root/lib
2021-09-17 17:05:16.686769: I tensorflow/stream_executor/cuda/cudart_stub.cc:29] Ignore above cudart dlerror if you do not have a GPU set up on your machine.
2021-09-17 17:05:25.954415: I tensorflow/compiler/jit/xla_cpu_device.cc:41] Not creating XLA devices, tf_xla_enable_xla_devices not set
2021-09-17 17:05:25.954651: W tensorflow/stream_executor/platform/default/dso_loader.cc:60] Could not load dynamic library 'libcuda.so.1'; dlerror: libcuda.so.1: cannot open shared object file: No such file or directory; LD_LIBRARY_PATH: /home/stefanovergani/root/lib
2021-09-17 17:05:25.954673: W tensorflow/stream_executor/cuda/cuda_driver.cc:326] failed call to cuInit: UNKNOWN ERROR (303)
2021-09-17 17:05:25.954700: I tensorflow/stream_executor/cuda/cuda_diagnostics.cc:156] kernel driver does not appear to be running on this host (stefano-xps-13): /proc/driver/nvidia/version does not exist
2021-09-17 17:05:25.954999: I tensorflow/core/platform/cpu_feature_guard.cc:142] This TensorFlow binary is optimized with oneAPI Deep Neural Network Library (oneDNN) to use the following CPU instructions in performance-critical operations:  AVX2 FMA
To enable them in other operations, rebuild TensorFlow with the appropriate compiler flags.
2021-09-17 17:05:25.955417: I tensorflow/compiler/jit/xla_gpu_device.cc:99] Not creating XLA devices, tf_xla_enable_xla_devices not set
2021-09-17 17:05:25.956143: W tensorflow/core/framework/cpu_allocator_impl.cc:80] Allocation of 576000000 exceeds 10% of free system memory.
2021-09-17 17:05:26.385469: W tensorflow/core/framework/cpu_allocator_impl.cc:80] Allocation of 384000000 exceeds 10% of free system memory.
2021-09-17 17:05:29.678556: W tensorflow/core/framework/cpu_allocator_impl.cc:80] Allocation of 576000000 exceeds 10% of free system memory.
Heap Status At Starting : 
Heap Size :  4346151  bytes

Partition of a set of 38497 objects. Total size = 4346183 bytes.
 Index  Count   %     Size   % Cumulative  % Kind (class / dict of class)
     0  11212  29   989097  23    989097  23 str
     1   9495  25   693712  16   1682809  39 tuple
     2   2474   6   357800   8   2040609  47 types.CodeType
     3   5026  13   354974   8   2395583  55 bytes
     4    445   1   336952   8   2732535  63 type
     5   2282   6   310352   7   3042887  70 function
     6    445   1   245048   6   3287935  76 dict of type
     7     99   0   173920   4   3461855  80 dict of module
     8    253   1   120008   3   3581863  82 dict (no owner)
     9   1092   3    87360   2   3669223  84 types.WrapperDescriptorType
<117 more rows. Type e.g. '_.more' to view.>
2.4.1
x_train_temp.shape (10000, 200, 200, 3)
x_test_temp.shape (2000, 200, 200, 3)
y_train.shape (10000,)
y_test.shape (2000,)
[[1. 0. 0.]
 [1. 0. 0.]
 [1. 0. 0.]
 ...
 [0. 1. 0.]
 [0. 1. 0.]
 [1. 0. 0.]]
y_train_bin.shape (10000, 3)
y_test_bin.shape (2000, 3)
Before: 0 255
After: 0.0 1.0
Test Data Shape after conversion to float
200
200
200
200
input_shape (200, 200, 3)
x_train[0].shape[0] 200
x_train[0].shape[1] 200
x_train[0].shape[2] 3
Traceback (most recent call last):
  File "keras_neutrino_densnet_169_dataset.py", line 632, in <module>
    model_evaluate_kwargs={"steps": vote_batches},
  File "/home/stefanovergani/colearn_2021_04_16/colearn/colearn_keras/keras_learner.py", line 77, in __init__
    self.vote_score: float = self.test(self.train_loader)
  File "/home/stefanovergani/colearn_2021_04_16/colearn/colearn_keras/keras_learner.py", line 160, in test
    **self.model_evaluate_kwargs)
  File "/home/stefanovergani/anaconda3/envs/colearn/lib/python3.7/site-packages/tensorflow/python/keras/engine/training.py", line 1389, in evaluate
    tmp_logs = self.test_function(iterator)
  File "/home/stefanovergani/anaconda3/envs/colearn/lib/python3.7/site-packages/tensorflow/python/eager/def_function.py", line 828, in __call__
    result = self._call(*args, **kwds)
  File "/home/stefanovergani/anaconda3/envs/colearn/lib/python3.7/site-packages/tensorflow/python/eager/def_function.py", line 871, in _call
    self._initialize(args, kwds, add_initializers_to=initializers)
  File "/home/stefanovergani/anaconda3/envs/colearn/lib/python3.7/site-packages/tensorflow/python/eager/def_function.py", line 726, in _initialize
    *args, **kwds))
  File "/home/stefanovergani/anaconda3/envs/colearn/lib/python3.7/site-packages/tensorflow/python/eager/function.py", line 2969, in _get_concrete_function_internal_garbage_collected
    graph_function, _ = self._maybe_define_function(args, kwargs)
  File "/home/stefanovergani/anaconda3/envs/colearn/lib/python3.7/site-packages/tensorflow/python/eager/function.py", line 3361, in _maybe_define_function
    graph_function = self._create_graph_function(args, kwargs)
  File "/home/stefanovergani/anaconda3/envs/colearn/lib/python3.7/site-packages/tensorflow/python/eager/function.py", line 3206, in _create_graph_function
    capture_by_value=self._capture_by_value),
  File "/home/stefanovergani/anaconda3/envs/colearn/lib/python3.7/site-packages/tensorflow/python/framework/func_graph.py", line 990, in func_graph_from_py_func
    func_outputs = python_func(*func_args, **func_kwargs)
  File "/home/stefanovergani/anaconda3/envs/colearn/lib/python3.7/site-packages/tensorflow/python/eager/def_function.py", line 634, in wrapped_fn
    out = weak_wrapped_fn().__wrapped__(*args, **kwds)
  File "/home/stefanovergani/anaconda3/envs/colearn/lib/python3.7/site-packages/tensorflow/python/framework/func_graph.py", line 977, in wrapper
    raise e.ag_error_metadata.to_exception(e)
ValueError: in user code:

    /home/stefanovergani/anaconda3/envs/colearn/lib/python3.7/site-packages/tensorflow/python/keras/engine/training.py:1233 test_function  *
        return step_function(self, iterator)
    /home/stefanovergani/anaconda3/envs/colearn/lib/python3.7/site-packages/tensorflow/python/keras/engine/training.py:1224 step_function  **
        outputs = model.distribute_strategy.run(run_step, args=(data,))
    /home/stefanovergani/anaconda3/envs/colearn/lib/python3.7/site-packages/tensorflow/python/distribute/distribute_lib.py:1259 run
        return self._extended.call_for_each_replica(fn, args=args, kwargs=kwargs)
    /home/stefanovergani/anaconda3/envs/colearn/lib/python3.7/site-packages/tensorflow/python/distribute/distribute_lib.py:2730 call_for_each_replica
        return self._call_for_each_replica(fn, args, kwargs)
    /home/stefanovergani/anaconda3/envs/colearn/lib/python3.7/site-packages/tensorflow/python/distribute/distribute_lib.py:3417 _call_for_each_replica
        return fn(*args, **kwargs)
    /home/stefanovergani/anaconda3/envs/colearn/lib/python3.7/site-packages/tensorflow/python/keras/engine/training.py:1217 run_step  **
        outputs = model.test_step(data)
    /home/stefanovergani/anaconda3/envs/colearn/lib/python3.7/site-packages/tensorflow/python/keras/engine/training.py:1183 test_step
        y_pred = self(x, training=False)
    /home/stefanovergani/anaconda3/envs/colearn/lib/python3.7/site-packages/tensorflow/python/keras/engine/base_layer.py:998 __call__
        input_spec.assert_input_compatibility(self.input_spec, inputs, self.name)
    /home/stefanovergani/anaconda3/envs/colearn/lib/python3.7/site-packages/tensorflow/python/keras/engine/input_spec.py:274 assert_input_compatibility
        ', found shape=' + display_shape(x.shape))

    ValueError: Input 0 is incompatible with layer model: expected shape=(None, 200, 200, 3), found shape=(200, 200, 3)

